2021/02/18 12:08:31 Attempt 1 of http call to http://10.0.0.7:16384/sendlogstoartifacts/info
2021/02/18 12:08:31 Attempt 1 of http call to http://10.0.0.7:16384/sendlogstoartifacts/status
[2021-02-18T12:08:32.994177] Entering context manager injector.
[context_manager_injector.py] Command line Options: Namespace(inject=['ProjectPythonPath:context_managers.ProjectPythonPath', 'RunHistory:context_managers.RunHistory', 'TrackUserError:context_managers.TrackUserError'], invocation=['train.py', '--C', '3', '--max_iter', '10'])
Script type = None
Starting the daemon thread to refresh tokens in background for process with pid = 105
[2021-02-18T12:08:34.387251] Entering Run History Context Manager.
[2021-02-18T12:08:35.274760] Current directory: /mnt/batch/tasks/shared/LS_root/jobs/quick-starts-ws-139115/azureml/hd_d8152258-f239-450f-87fb-48da1a78648f_3/mounts/workspaceblobstore/azureml/HD_d8152258-f239-450f-87fb-48da1a78648f_3
[2021-02-18T12:08:35.275580] Preparing to call script [train.py] with arguments:['--C', '3', '--max_iter', '10']
[2021-02-18T12:08:35.282626] After variable expansion, calling script [train.py] with arguments:['--C', '3', '--max_iter', '10']

Performing interactive authentication. Please follow the instructions on the terminal.
To sign in, use a web browser to open the page https://microsoft.com/devicelogin and enter the code RWPPJ7LLR to authenticate.
Starting the daemon thread to refresh tokens in background for process with pid = 105


[2021-02-18T12:23:55.098627] The experiment failed. Finalizing run...
Cleaning up all outstanding Run operations, waiting 900.0 seconds
1 items cleaning up...
Cleanup took 0.06682705879211426 seconds
[2021-02-18T12:23:55.351832] Logging warning in history service: ERROR:: RunHistoryFinalization  failed. . Exception Details:Traceback (most recent call last):
  File "/opt/miniconda/lib/python3.6/site-packages/azureml/_base_sdk_common/common.py", line 579, in perform_interactive_login
    use_cert_sn_issuer=use_cert_sn_issuer)
  File "/opt/miniconda/lib/python3.6/site-packages/azureml/_vendor/azure_cli_core/_profile.py", line 228, in find_subscriptions_on_login
    tenant, self._ad_resource_uri)
  File "/opt/miniconda/lib/python3.6/site-packages/azureml/_vendor/azure_cli_core/_profile.py", line 786, in find_through_interactive_flow
    token_entry = context.acquire_token_with_device_code(resource, code, _CLIENT_ID)
  File "/opt/miniconda/lib/python3.6/site-packages/adal/authentication_context.py", line 311, in acquire_token_with_device_code
    return self._acquire_token(token_func, user_code_info.get('correlation_id', None))
  File "/opt/miniconda/lib/python3.6/site-packages/adal/authentication_context.py", line 128, in _acquire_token
    return token_func(self)
  File "/opt/miniconda/lib/python3.6/site-packages/adal/authentication_context.py", line 304, in token_func
    token = token_request.get_token_with_device_code(user_code_info)
  File "/opt/miniconda/lib/python3.6/site-packages/adal/token_request.py", line 392, in get_token_with_device_code
    token = client.get_token_with_polling(oauth_parameters, interval, expires_in)
  File "/opt/miniconda/lib/python3.6/site-packages/adal/oauth2_client.py", line 362, in get_token_with_polling
    wire_response)
adal.adal_error.AdalError: Unexpected polling state code_expired

During handling of the above exception, another exception occurred:

Traceback (most recent call last):
  File "/mnt/batch/tasks/shared/LS_root/jobs/quick-starts-ws-139115/azureml/hd_d8152258-f239-450f-87fb-48da1a78648f_3/mounts/workspaceblobstore/azureml/HD_d8152258-f239-450f-87fb-48da1a78648f_3/azureml-setup/context_manager_injector.py", line 210, in execute_with_context
    runpy.run_path(sys.argv[0], globals(), run_name="__main__")
  File "/opt/miniconda/lib/python3.6/runpy.py", line 263, in run_path
    pkg_name=pkg_name, script_name=fname)
  File "/opt/miniconda/lib/python3.6/runpy.py", line 96, in _run_module_code
    mod_name, mod_spec, pkg_name, script_name)
  File "/opt/miniconda/lib/python3.6/runpy.py", line 85, in _run_code
    exec(code, run_globals)
  File "train.py", line 27, in <module>
    workspace = Workspace(subscription_id, resource_group, workspace_name)
  File "/opt/miniconda/lib/python3.6/site-packages/azureml/core/workspace.py", line 178, in __init__
    auth = InteractiveLoginAuthentication()
  File "/opt/miniconda/lib/python3.6/site-packages/azureml/core/authentication.py", line 414, in __init__
    perform_interactive_login(tenant=tenant_id, cloud_type=self._cloud_type)
  File "/opt/miniconda/lib/python3.6/site-packages/azureml/_base_sdk_common/common.py", line 589, in perform_interactive_login
    raise AuthenticationException(err)
azureml.exceptions._azureml_exception.AuthenticationException: <unprintable AuthenticationException object>

During handling of the above exception, another exception occurred:

Traceback (most recent call last):
  File "/mnt/batch/tasks/shared/LS_root/jobs/quick-starts-ws-139115/azureml/hd_d8152258-f239-450f-87fb-48da1a78648f_3/mounts/workspaceblobstore/azureml/HD_d8152258-f239-450f-87fb-48da1a78648f_3/azureml-setup/context_manager_injector.py", line 239, in execute_with_context
    raise UserScriptException(baseEx).with_traceback(exceptionInfo[2])
  File "/mnt/batch/tasks/shared/LS_root/jobs/quick-starts-ws-139115/azureml/hd_d8152258-f239-450f-87fb-48da1a78648f_3/mounts/workspaceblobstore/azureml/HD_d8152258-f239-450f-87fb-48da1a78648f_3/azureml-setup/context_manager_injector.py", line 210, in execute_with_context
    runpy.run_path(sys.argv[0], globals(), run_name="__main__")
  File "/opt/miniconda/lib/python3.6/runpy.py", line 263, in run_path
    pkg_name=pkg_name, script_name=fname)
  File "/opt/miniconda/lib/python3.6/runpy.py", line 96, in _run_module_code
    mod_name, mod_spec, pkg_name, script_name)
  File "/opt/miniconda/lib/python3.6/runpy.py", line 85, in _run_code
    exec(code, run_globals)
  File "train.py", line 27, in <module>
    workspace = Workspace(subscription_id, resource_group, workspace_name)
  File "/opt/miniconda/lib/python3.6/site-packages/azureml/core/workspace.py", line 178, in __init__
    auth = InteractiveLoginAuthentication()
  File "/opt/miniconda/lib/python3.6/site-packages/azureml/core/authentication.py", line 414, in __init__
    perform_interactive_login(tenant=tenant_id, cloud_type=self._cloud_type)
  File "/opt/miniconda/lib/python3.6/site-packages/azureml/_base_sdk_common/common.py", line 589, in perform_interactive_login
    raise AuthenticationException(err)
UserScriptException: <unprintable UserScriptException object>

During handling of the above exception, another exception occurred:

Traceback (most recent call last):
  File "/mnt/batch/tasks/shared/LS_root/jobs/quick-starts-ws-139115/azureml/hd_d8152258-f239-450f-87fb-48da1a78648f_3/mounts/workspaceblobstore/azureml/HD_d8152258-f239-450f-87fb-48da1a78648f_3/azureml-setup/context_managers.py", line 354, in __exit__
    self.history_context.__exit__(*args)
  File "/opt/miniconda/lib/python3.6/site-packages/azureml/_history/utils/context_managers.py", line 56, in __exit__
    return self._exit_stack.__exit__(*args)
  File "/opt/miniconda/lib/python3.6/contextlib.py", line 380, in __exit__
    raise exc_details[1]
  File "/opt/miniconda/lib/python3.6/contextlib.py", line 365, in __exit__
    if cb(*exc_details):
  File "/opt/miniconda/lib/python3.6/contextlib.py", line 284, in _exit_wrapper
    return cm_exit(cm, *exc_details)
  File "/opt/miniconda/lib/python3.6/site-packages/azureml/_history/utils/log_scope.py", line 30, in __exit__
    self._logger.error("{0}: {1}\n{2}".format(etype, value, traceback))
  File "/opt/miniconda/lib/python3.6/site-packages/azureml/_common/exceptions.py", line 116, in __str__
    return self.__repr__()
  File "/opt/miniconda/lib/python3.6/site-packages/azureml/_common/exceptions.py", line 112, in __repr__
    self._serialize_json(indent=4))
  File "/opt/miniconda/lib/python3.6/site-packages/azureml/_common/exceptions.py", line 183, in _serialize_json
    return json.dumps(error_ret, indent=indent)
  File "/opt/miniconda/lib/python3.6/json/__init__.py", line 238, in dumps
    **kw).encode(obj)
  File "/opt/miniconda/lib/python3.6/json/encoder.py", line 201, in encode
    chunks = list(chunks)
  File "/opt/miniconda/lib/python3.6/json/encoder.py", line 430, in _iterencode
    yield from _iterencode_dict(o, _current_indent_level)
  File "/opt/miniconda/lib/python3.6/json/encoder.py", line 404, in _iterencode_dict
    yield from chunks
  File "/opt/miniconda/lib/python3.6/json/encoder.py", line 404, in _iterencode_dict
    yield from chunks
  File "/opt/miniconda/lib/python3.6/json/encoder.py", line 437, in _iterencode
    o = _default(o)
  File "/opt/miniconda/lib/python3.6/json/encoder.py", line 180, in default
    o.__class__.__name__)
TypeError: Object of type 'AdalError' is not JSON serializable

Starting the daemon thread to refresh tokens in background for process with pid = 105
[2021-02-18T12:23:55.423538] Writing error with error_code ServiceError to hosttool error file located at /mnt/batch/tasks/workitems/c6909190-41a4-4022-b42b-4492df341956/job-1/hd_d8152258-f239-450_18d2c984-521f-4d54-add7-9760c3a82ac2/wd/runTaskLetTask_error.json
Traceback (most recent call last):
  File "/opt/miniconda/lib/python3.6/site-packages/azureml/_base_sdk_common/common.py", line 579, in perform_interactive_login
    use_cert_sn_issuer=use_cert_sn_issuer)
  File "/opt/miniconda/lib/python3.6/site-packages/azureml/_vendor/azure_cli_core/_profile.py", line 228, in find_subscriptions_on_login
    tenant, self._ad_resource_uri)
  File "/opt/miniconda/lib/python3.6/site-packages/azureml/_vendor/azure_cli_core/_profile.py", line 786, in find_through_interactive_flow
    token_entry = context.acquire_token_with_device_code(resource, code, _CLIENT_ID)
  File "/opt/miniconda/lib/python3.6/site-packages/adal/authentication_context.py", line 311, in acquire_token_with_device_code
    return self._acquire_token(token_func, user_code_info.get('correlation_id', None))
  File "/opt/miniconda/lib/python3.6/site-packages/adal/authentication_context.py", line 128, in _acquire_token
    return token_func(self)
  File "/opt/miniconda/lib/python3.6/site-packages/adal/authentication_context.py", line 304, in token_func
    token = token_request.get_token_with_device_code(user_code_info)
  File "/opt/miniconda/lib/python3.6/site-packages/adal/token_request.py", line 392, in get_token_with_device_code
    token = client.get_token_with_polling(oauth_parameters, interval, expires_in)
  File "/opt/miniconda/lib/python3.6/site-packages/adal/oauth2_client.py", line 362, in get_token_with_polling
    wire_response)
adal.adal_error.AdalError: Unexpected polling state code_expired

During handling of the above exception, another exception occurred:

Traceback (most recent call last):
  File "/mnt/batch/tasks/shared/LS_root/jobs/quick-starts-ws-139115/azureml/hd_d8152258-f239-450f-87fb-48da1a78648f_3/mounts/workspaceblobstore/azureml/HD_d8152258-f239-450f-87fb-48da1a78648f_3/azureml-setup/context_manager_injector.py", line 210, in execute_with_context
    runpy.run_path(sys.argv[0], globals(), run_name="__main__")
  File "/opt/miniconda/lib/python3.6/runpy.py", line 263, in run_path
    pkg_name=pkg_name, script_name=fname)
  File "/opt/miniconda/lib/python3.6/runpy.py", line 96, in _run_module_code
    mod_name, mod_spec, pkg_name, script_name)
  File "/opt/miniconda/lib/python3.6/runpy.py", line 85, in _run_code
    exec(code, run_globals)
  File "train.py", line 27, in <module>
    workspace = Workspace(subscription_id, resource_group, workspace_name)
  File "/opt/miniconda/lib/python3.6/site-packages/azureml/core/workspace.py", line 178, in __init__
    auth = InteractiveLoginAuthentication()
  File "/opt/miniconda/lib/python3.6/site-packages/azureml/core/authentication.py", line 414, in __init__
    perform_interactive_login(tenant=tenant_id, cloud_type=self._cloud_type)
  File "/opt/miniconda/lib/python3.6/site-packages/azureml/_base_sdk_common/common.py", line 589, in perform_interactive_login
    raise AuthenticationException(err)
azureml.exceptions._azureml_exception.AuthenticationException: <unprintable AuthenticationException object>

During handling of the above exception, another exception occurred:

Traceback (most recent call last):
  File "/mnt/batch/tasks/shared/LS_root/jobs/quick-starts-ws-139115/azureml/hd_d8152258-f239-450f-87fb-48da1a78648f_3/mounts/workspaceblobstore/azureml/HD_d8152258-f239-450f-87fb-48da1a78648f_3/azureml-setup/context_manager_injector.py", line 239, in execute_with_context
    raise UserScriptException(baseEx).with_traceback(exceptionInfo[2])
  File "/mnt/batch/tasks/shared/LS_root/jobs/quick-starts-ws-139115/azureml/hd_d8152258-f239-450f-87fb-48da1a78648f_3/mounts/workspaceblobstore/azureml/HD_d8152258-f239-450f-87fb-48da1a78648f_3/azureml-setup/context_manager_injector.py", line 210, in execute_with_context
    runpy.run_path(sys.argv[0], globals(), run_name="__main__")
  File "/opt/miniconda/lib/python3.6/runpy.py", line 263, in run_path
    pkg_name=pkg_name, script_name=fname)
  File "/opt/miniconda/lib/python3.6/runpy.py", line 96, in _run_module_code
    mod_name, mod_spec, pkg_name, script_name)
  File "/opt/miniconda/lib/python3.6/runpy.py", line 85, in _run_code
    exec(code, run_globals)
  File "train.py", line 27, in <module>
    workspace = Workspace(subscription_id, resource_group, workspace_name)
  File "/opt/miniconda/lib/python3.6/site-packages/azureml/core/workspace.py", line 178, in __init__
    auth = InteractiveLoginAuthentication()
  File "/opt/miniconda/lib/python3.6/site-packages/azureml/core/authentication.py", line 414, in __init__
    perform_interactive_login(tenant=tenant_id, cloud_type=self._cloud_type)
  File "/opt/miniconda/lib/python3.6/site-packages/azureml/_base_sdk_common/common.py", line 589, in perform_interactive_login
    raise AuthenticationException(err)
UserScriptException: <unprintable UserScriptException object>

During handling of the above exception, another exception occurred:

Traceback (most recent call last):
  File "train.py", line 27, in <module>
    workspace = Workspace(subscription_id, resource_group, workspace_name)
  File "/opt/miniconda/lib/python3.6/site-packages/azureml/core/workspace.py", line 178, in __init__
    auth = InteractiveLoginAuthentication()
  File "/opt/miniconda/lib/python3.6/site-packages/azureml/core/authentication.py", line 414, in __init__
    perform_interactive_login(tenant=tenant_id, cloud_type=self._cloud_type)
  File "/opt/miniconda/lib/python3.6/site-packages/azureml/_base_sdk_common/common.py", line 589, in perform_interactive_login
    raise AuthenticationException(err)
UserScriptException: <unprintable UserScriptException object>

During handling of the above exception, another exception occurred:

Traceback (most recent call last):
  File "/mnt/batch/tasks/shared/LS_root/jobs/quick-starts-ws-139115/azureml/hd_d8152258-f239-450f-87fb-48da1a78648f_3/mounts/workspaceblobstore/azureml/HD_d8152258-f239-450f-87fb-48da1a78648f_3/azureml-setup/context_manager_injector.py", line 423, in <module>
    execute_with_context(cm_objects, options.invocation)
  File "/mnt/batch/tasks/shared/LS_root/jobs/quick-starts-ws-139115/azureml/hd_d8152258-f239-450f-87fb-48da1a78648f_3/mounts/workspaceblobstore/azureml/HD_d8152258-f239-450f-87fb-48da1a78648f_3/azureml-setup/context_manager_injector.py", line 264, in execute_with_context
    print("Error occurred when setting run status to Finalizing: {}".format(ex))
  File "/mnt/batch/tasks/shared/LS_root/jobs/quick-starts-ws-139115/azureml/hd_d8152258-f239-450f-87fb-48da1a78648f_3/mounts/workspaceblobstore/azureml/HD_d8152258-f239-450f-87fb-48da1a78648f_3/azureml-setup/_vendor_contextlib2.py", line 393, in __exit__
    _reraise_with_existing_context(exc_details)
  File "/mnt/batch/tasks/shared/LS_root/jobs/quick-starts-ws-139115/azureml/hd_d8152258-f239-450f-87fb-48da1a78648f_3/mounts/workspaceblobstore/azureml/HD_d8152258-f239-450f-87fb-48da1a78648f_3/azureml-setup/_vendor_contextlib2.py", line 261, in _reraise_with_existing_context
    raise exc_details[1]
  File "/mnt/batch/tasks/shared/LS_root/jobs/quick-starts-ws-139115/azureml/hd_d8152258-f239-450f-87fb-48da1a78648f_3/mounts/workspaceblobstore/azureml/HD_d8152258-f239-450f-87fb-48da1a78648f_3/azureml-setup/_vendor_contextlib2.py", line 382, in __exit__
    if cb(*exc_details):
  File "/mnt/batch/tasks/shared/LS_root/jobs/quick-starts-ws-139115/azureml/hd_d8152258-f239-450f-87fb-48da1a78648f_3/mounts/workspaceblobstore/azureml/HD_d8152258-f239-450f-87fb-48da1a78648f_3/azureml-setup/_vendor_contextlib2.py", line 314, in _exit_wrapper
    return cm_exit(cm, *exc_details)
  File "/mnt/batch/tasks/shared/LS_root/jobs/quick-starts-ws-139115/azureml/hd_d8152258-f239-450f-87fb-48da1a78648f_3/mounts/workspaceblobstore/azureml/HD_d8152258-f239-450f-87fb-48da1a78648f_3/azureml-setup/context_manager_injector.py", line 80, in __exit__
    self.context_manager.__exit__(*exc_details)
  File "/mnt/batch/tasks/shared/LS_root/jobs/quick-starts-ws-139115/azureml/hd_d8152258-f239-450f-87fb-48da1a78648f_3/mounts/workspaceblobstore/azureml/HD_d8152258-f239-450f-87fb-48da1a78648f_3/azureml-setup/context_managers.py", line 354, in __exit__
    self.history_context.__exit__(*args)
  File "/opt/miniconda/lib/python3.6/site-packages/azureml/_history/utils/context_managers.py", line 56, in __exit__
    return self._exit_stack.__exit__(*args)
  File "/opt/miniconda/lib/python3.6/contextlib.py", line 380, in __exit__
    raise exc_details[1]
  File "/opt/miniconda/lib/python3.6/contextlib.py", line 365, in __exit__
    if cb(*exc_details):
  File "/opt/miniconda/lib/python3.6/contextlib.py", line 284, in _exit_wrapper
    return cm_exit(cm, *exc_details)
  File "/opt/miniconda/lib/python3.6/site-packages/azureml/_history/utils/log_scope.py", line 30, in __exit__
    self._logger.error("{0}: {1}\n{2}".format(etype, value, traceback))
  File "/opt/miniconda/lib/python3.6/site-packages/azureml/_common/exceptions.py", line 116, in __str__
    return self.__repr__()
  File "/opt/miniconda/lib/python3.6/site-packages/azureml/_common/exceptions.py", line 112, in __repr__
    self._serialize_json(indent=4))
  File "/opt/miniconda/lib/python3.6/site-packages/azureml/_common/exceptions.py", line 183, in _serialize_json
    return json.dumps(error_ret, indent=indent)
  File "/opt/miniconda/lib/python3.6/json/__init__.py", line 238, in dumps
    **kw).encode(obj)
  File "/opt/miniconda/lib/python3.6/json/encoder.py", line 201, in encode
    chunks = list(chunks)
  File "/opt/miniconda/lib/python3.6/json/encoder.py", line 430, in _iterencode
    yield from _iterencode_dict(o, _current_indent_level)
  File "/opt/miniconda/lib/python3.6/json/encoder.py", line 404, in _iterencode_dict
    yield from chunks
  File "/opt/miniconda/lib/python3.6/json/encoder.py", line 404, in _iterencode_dict
    yield from chunks
  File "/opt/miniconda/lib/python3.6/json/encoder.py", line 437, in _iterencode
    o = _default(o)
  File "/opt/miniconda/lib/python3.6/json/encoder.py", line 180, in default
    o.__class__.__name__)
TypeError: Object of type 'AdalError' is not JSON serializable

[2021-02-18T12:23:55.514773] Finished context manager injector with Exception.
Exception in thread Thread-1:
Traceback (most recent call last):
  File "/opt/miniconda/lib/python3.6/threading.py", line 916, in _bootstrap_inner
    self.run()
  File "/opt/miniconda/lib/python3.6/threading.py", line 864, in run
    self._target(*self._args, **self._kwargs)
  File "/mnt/batch/tasks/shared/LS_root/jobs/quick-starts-ws-139115/azureml/hd_d8152258-f239-450f-87fb-48da1a78648f_3/mounts/workspaceblobstore/azureml/HD_d8152258-f239-450f-87fb-48da1a78648f_3/azureml-setup/_tracing.py", line 674, in worker
    max_flush_interval, last_flushed, logger)
  File "/mnt/batch/tasks/shared/LS_root/jobs/quick-starts-ws-139115/azureml/hd_d8152258-f239-450f-87fb-48da1a78648f_3/mounts/workspaceblobstore/azureml/HD_d8152258-f239-450f-87fb-48da1a78648f_3/azureml-setup/_tracing.py", line 721, in flush
    flush_internal()
  File "/mnt/batch/tasks/shared/LS_root/jobs/quick-starts-ws-139115/azureml/hd_d8152258-f239-450f-87fb-48da1a78648f_3/mounts/workspaceblobstore/azureml/HD_d8152258-f239-450f-87fb-48da1a78648f_3/azureml-setup/_tracing.py", line 710, in flush_internal
    RunHistoryExporter._retry(make_req, 'Export Spans', logger)
  File "/mnt/batch/tasks/shared/LS_root/jobs/quick-starts-ws-139115/azureml/hd_d8152258-f239-450f-87fb-48da1a78648f_3/mounts/workspaceblobstore/azureml/HD_d8152258-f239-450f-87fb-48da1a78648f_3/azureml-setup/_tracing.py", line 772, in _retry
    return func()
  File "/mnt/batch/tasks/shared/LS_root/jobs/quick-starts-ws-139115/azureml/hd_d8152258-f239-450f-87fb-48da1a78648f_3/mounts/workspaceblobstore/azureml/HD_d8152258-f239-450f-87fb-48da1a78648f_3/azureml-setup/_tracing.py", line 698, in make_req
    req = request.Request(url, data=json.dumps(payload).encode(), headers=headers, method='POST')
  File "/opt/miniconda/lib/python3.6/json/__init__.py", line 231, in dumps
    return _default_encoder.encode(obj)
  File "/opt/miniconda/lib/python3.6/json/encoder.py", line 199, in encode
    chunks = self.iterencode(o, _one_shot=True)
  File "/opt/miniconda/lib/python3.6/json/encoder.py", line 257, in iterencode
    return _iterencode(o, 0)
  File "/opt/miniconda/lib/python3.6/json/encoder.py", line 180, in default
    o.__class__.__name__)
TypeError: Object of type 'AdalError' is not JSON serializable

2021/02/18 12:23:57 Succeeded to parse control script error: /mnt/batch/tasks/workitems/c6909190-41a4-4022-b42b-4492df341956/job-1/hd_d8152258-f239-450_18d2c984-521f-4d54-add7-9760c3a82ac2/wd/runTaskLetTask_error.json to json
2021/02/18 12:23:57 Failed to run the wrapper cmd with err: exit status 1
2021/02/18 12:23:57 Attempt 1 of http call to http://10.0.0.7:16384/sendlogstoartifacts/status
2021/02/18 12:23:57 mpirun version string: {
Intel(R) MPI Library for Linux* OS, Version 2018 Update 3 Build 20180411 (id: 18329)
Copyright 2003-2018 Intel Corporation.
}
2021/02/18 12:23:57 MPI publisher: intel ; version: 2018
2021/02/18 12:23:57 Process Exiting with Code:  1
